INFO Watching for file changes with StatReloader
INFO Watching for file changes with StatReloader
INFO Watching for file changes with StatReloader
INFO Watching for file changes with StatReloader
INFO /backend/config/settings.py changed, reloading.
INFO Watching for file changes with StatReloader
WARNING Not Found: /api/slides
WARNING Not Found: /favicon.ico
ERROR Internal Server Error: /api/articles
Traceback (most recent call last):
  File "/usr/local/lib/python3.8/site-packages/rest_framework/fields.py", line 457, in get_attribute
    return get_attribute(instance, self.source_attrs)
  File "/usr/local/lib/python3.8/site-packages/rest_framework/fields.py", line 97, in get_attribute
    instance = getattr(instance, attr)
AttributeError: 'QuerySet' object has no attribute 'title'

During handling of the above exception, another exception occurred:

Traceback (most recent call last):
  File "/usr/local/lib/python3.8/site-packages/django/core/handlers/exception.py", line 47, in inner
    response = get_response(request)
  File "/usr/local/lib/python3.8/site-packages/django/core/handlers/base.py", line 181, in _get_response
    response = wrapped_callback(request, *callback_args, **callback_kwargs)
  File "/usr/local/lib/python3.8/site-packages/django/views/decorators/csrf.py", line 54, in wrapped_view
    return view_func(*args, **kwargs)
  File "/usr/local/lib/python3.8/site-packages/django/views/generic/base.py", line 70, in view
    return self.dispatch(request, *args, **kwargs)
  File "/usr/local/lib/python3.8/site-packages/rest_framework/views.py", line 509, in dispatch
    response = self.handle_exception(exc)
  File "/usr/local/lib/python3.8/site-packages/rest_framework/views.py", line 469, in handle_exception
    self.raise_uncaught_exception(exc)
  File "/usr/local/lib/python3.8/site-packages/rest_framework/views.py", line 480, in raise_uncaught_exception
    raise exc
  File "/usr/local/lib/python3.8/site-packages/rest_framework/views.py", line 506, in dispatch
    response = handler(request, *args, **kwargs)
  File "/backend/api/views.py", line 15, in get
    return Response(status=status.HTTP_200_OK, data=articles_serialized.data)
  File "/usr/local/lib/python3.8/site-packages/rest_framework/serializers.py", line 548, in data
    ret = super().data
  File "/usr/local/lib/python3.8/site-packages/rest_framework/serializers.py", line 246, in data
    self._data = self.to_representation(self.instance)
  File "/usr/local/lib/python3.8/site-packages/rest_framework/serializers.py", line 502, in to_representation
    attribute = field.get_attribute(instance)
  File "/usr/local/lib/python3.8/site-packages/rest_framework/fields.py", line 490, in get_attribute
    raise type(exc)(msg)
AttributeError: Got AttributeError when attempting to get a value for field `title` on serializer `ArticleSerializer`.
The serializer field might be named incorrectly and not match any attribute or key on the `QuerySet` instance.
Original exception text was: 'QuerySet' object has no attribute 'title'.
INFO /backend/api/views.py changed, reloading.
INFO Watching for file changes with StatReloader
INFO Watching for file changes with StatReloader
INFO Watching for file changes with StatReloader
WARNING Not Found: /api/slides
INFO Watching for file changes with StatReloader
INFO /backend/config/settings.py changed, reloading.
INFO Watching for file changes with StatReloader
INFO /backend/config/settings.py changed, reloading.
INFO Watching for file changes with StatReloader
INFO Watching for file changes with StatReloader
WARNING Not Found: /api/slides
WARNING Not Found: /favicon.ico
WARNING Not Found: /api/slides
ERROR Internal Server Error: /api/articles
Traceback (most recent call last):
  File "/usr/local/lib/python3.8/site-packages/django/db/backends/utils.py", line 84, in _execute
    return self.cursor.execute(sql, params)
  File "/usr/local/lib/python3.8/site-packages/django/db/backends/sqlite3/base.py", line 423, in execute
    return Database.Cursor.execute(self, query, params)
sqlite3.OperationalError: no such table: Article

The above exception was the direct cause of the following exception:

Traceback (most recent call last):
  File "/usr/local/lib/python3.8/site-packages/django/core/handlers/exception.py", line 47, in inner
    response = get_response(request)
  File "/usr/local/lib/python3.8/site-packages/django/core/handlers/base.py", line 181, in _get_response
    response = wrapped_callback(request, *callback_args, **callback_kwargs)
  File "/usr/local/lib/python3.8/site-packages/django/views/decorators/csrf.py", line 54, in wrapped_view
    return view_func(*args, **kwargs)
  File "/usr/local/lib/python3.8/site-packages/django/views/generic/base.py", line 70, in view
    return self.dispatch(request, *args, **kwargs)
  File "/usr/local/lib/python3.8/site-packages/rest_framework/views.py", line 509, in dispatch
    response = self.handle_exception(exc)
  File "/usr/local/lib/python3.8/site-packages/rest_framework/views.py", line 469, in handle_exception
    self.raise_uncaught_exception(exc)
  File "/usr/local/lib/python3.8/site-packages/rest_framework/views.py", line 480, in raise_uncaught_exception
    raise exc
  File "/usr/local/lib/python3.8/site-packages/rest_framework/views.py", line 506, in dispatch
    response = handler(request, *args, **kwargs)
  File "/backend/api/views.py", line 15, in get
    return Response(status=status.HTTP_200_OK, data=articles_serialized.data)
  File "/usr/local/lib/python3.8/site-packages/rest_framework/serializers.py", line 745, in data
    ret = super().data
  File "/usr/local/lib/python3.8/site-packages/rest_framework/serializers.py", line 246, in data
    self._data = self.to_representation(self.instance)
  File "/usr/local/lib/python3.8/site-packages/rest_framework/serializers.py", line 663, in to_representation
    return [
  File "/usr/local/lib/python3.8/site-packages/django/db/models/query.py", line 280, in __iter__
    self._fetch_all()
  File "/usr/local/lib/python3.8/site-packages/django/db/models/query.py", line 1324, in _fetch_all
    self._result_cache = list(self._iterable_class(self))
  File "/usr/local/lib/python3.8/site-packages/django/db/models/query.py", line 51, in __iter__
    results = compiler.execute_sql(chunked_fetch=self.chunked_fetch, chunk_size=self.chunk_size)
  File "/usr/local/lib/python3.8/site-packages/django/db/models/sql/compiler.py", line 1175, in execute_sql
    cursor.execute(sql, params)
  File "/usr/local/lib/python3.8/site-packages/django/db/backends/utils.py", line 66, in execute
    return self._execute_with_wrappers(sql, params, many=False, executor=self._execute)
  File "/usr/local/lib/python3.8/site-packages/django/db/backends/utils.py", line 75, in _execute_with_wrappers
    return executor(sql, params, many, context)
  File "/usr/local/lib/python3.8/site-packages/django/db/backends/utils.py", line 84, in _execute
    return self.cursor.execute(sql, params)
  File "/usr/local/lib/python3.8/site-packages/django/db/utils.py", line 90, in __exit__
    raise dj_exc_value.with_traceback(traceback) from exc_value
  File "/usr/local/lib/python3.8/site-packages/django/db/backends/utils.py", line 84, in _execute
    return self.cursor.execute(sql, params)
  File "/usr/local/lib/python3.8/site-packages/django/db/backends/sqlite3/base.py", line 423, in execute
    return Database.Cursor.execute(self, query, params)
django.db.utils.OperationalError: no such table: Article
WARNING Not Found: /api/slides
WARNING Not Found: /api/slides
WARNING Not Found: /media/previews/IMG_1169.JPG
WARNING Not Found: /media/previews/IMG_1161.JPG
WARNING Not Found: /media/previews/IMG_1169.JPG
WARNING Not Found: /media/previews/IMG_1161.JPG
WARNING Not Found: /media/previews/IMG_1169.JPG
WARNING Not Found: /media/previews/IMG_1161.JPG
WARNING Not Found: /media/previews/IMG_1169.JPG
WARNING Not Found: /media/previews/IMG_1161.JPG
WARNING Not Found: /media/previews/IMG_1169.JPG
WARNING Not Found: /media/previews/IMG_1161.JPG
WARNING Not Found: /media/previews/IMG_1169.JPG
WARNING Not Found: /media/previews/IMG_1161.JPG
WARNING Not Found: /media/previews/IMG_1169.JPG
WARNING Not Found: /media/previews/IMG_1161.JPG
